<sdf version='1.11'>
    <model name='observer'>
        <plugin name='dataset_generation::ObserverRobotController'
        filename='ObserverRobotController' />

        <pose>0 0 0 0 0 0</pose>

        <!-- Link for the base of the observer. The observer base is jointed to the world with two
        prismatic joints allowing XY motion -->
        <link name='observer_link'>
            <inertial>
                <mass>1</mass>
                <pose>0 0 0 0 0 0</pose>
            </inertial>
            <visual name='observer_base_visual'>
                <geometry>
                    <box>
                        <size>0.5 0.5 0.1</size>
                    </box>
                </geometry>
                <material>
                    <ambient>0 0 1 1</ambient>
                    <diffuse>0 0 1 1</diffuse>
                    <specular>1 1 1 1</specular>
                </material>
            </visual>
            <pose>0 0 0 0 0 0</pose>
        </link>
        <link name="x_slider_link" />
        <link name="z_rotator_link" />
        <joint name="world_x_slider" type="prismatic">
            <parent>world</parent>
            <child>x_slider_link</child>
            <axis>
                <xyz>1 0 0</xyz>
                <dynamics>
                    <damping>3.0</damping>
                    <friction>0.1</friction>
                </dynamics>
            </axis>
        </joint>
        <joint name="world_y_slider" type="prismatic">
            <parent>x_slider_link</parent>
            <child>z_rotator_link</child>
            <axis>
                <xyz>0 1 0</xyz>
                <dynamics>
                    <damping>3.0</damping>
                    <friction>0.1</friction>
                </dynamics>
            </axis>
        </joint>
        <joint name="z_rotator" type="revolute">
            <parent>z_rotator_link</parent>
            <child>observer_link</child>
            <axis>
                <xyz>0 0 1</xyz>
                <dynamics>
                    <damping>3.0</damping>
                    <friction>0.1</friction>
                </dynamics>
            </axis>
        </joint>

        <!-- The Z slider moves the base_link up and down -->
        <link name='z_slider_link'>
            <gravity>false</gravity>
            <visual name='z_slider_visual'>
                <geometry>
                    <box>
                        <size>0.1 0.1 2.5</size>
                    </box>
                </geometry>
                <material>
                    <ambient>1 0 0 1</ambient>
                    <diffuse>1 0 0 1</diffuse>
                    <specular>1 1 1 1</specular>
                </material>
            </visual>
            <pose>0 0 -0.25 0 0 0</pose>
        </link>
        <joint name="z_slider_joint" type="prismatic">
            <parent>observer_link</parent>
            <child>z_slider_link</child>
            <axis>
                <xyz>0 0 1</xyz>
                <limit>
                    <lower>-1</lower>
                    <upper>2.5</upper>
                </limit>
                <dynamics>
                    <damping>10.0</damping>
                    <friction>0.1</friction>
                </dynamics>
            </axis>
        </joint>

        <!-- The z_boom link extends forward from the top of the z_slider,
        this makes it more difficult to do pure rotations, which SLAM systems can struggle with. -->
        <link name='z_boom_link'>
            <gravity>false</gravity>
            <visual name='z_boom_visual'>
                <geometry>
                    <box>
                        <size>0.5 0.1 0.1</size>
                    </box>
                </geometry>
                <material>
                    <ambient>0 1 0 1</ambient>
                    <diffuse>0 1 0 1</diffuse>
                    <specular>1 1 1 1</specular>
                </material>
            </visual>
            <pose>0.25 0 1 0 0 0</pose>
        </link>
        <joint name="z_boom_joint" type="fixed">
            <parent>z_slider_link</parent>
            <child>z_boom_link</child>
        </joint>

        <!-- The base link is where all data is collected. It contains the IMU, 3 cameras (stereo
        and segmentation), and is where ground truth is recorded. -->
        <link name="base_link">
            <gravity>false</gravity>
            <visual name='base_visual'>
                <geometry>
                    <box>
                        <size>0.1 0.5 0.25</size>
                    </box>
                </geometry>
                <material>
                    <ambient>1 1 0 1</ambient>
                    <diffuse>1 1 0 1</diffuse>
                    <specular>1 1 1 1</specular>
                </material>
            </visual>
            <pose>0.5 0 1 0 0 0</pose>
            <sensor name='observer_camera' type='camera'>
                <topic>observer/left</topic>
                <camera>
                    <camera_info_topic>observer/left_info</camera_info_topic>

                    <horizontal_fov>1.047</horizontal_fov>
                    <image>
                        <width>1280</width>
                        <height>800</height>
                    </image>
                    <clip>
                        <near>0.1</near>
                        <far>100</far>
                    </clip>
                </camera>
                <always_on>1</always_on>
                <update_rate>30</update_rate>
                <visualize>true</visualize>
                <pose>0 -0.0375 0 0 0 0</pose>
            </sensor>
            <sensor name='observer_camera_right' type='camera'>
                <topic>observer/right</topic>
                <camera>
                    <horizontal_fov>0.6</horizontal_fov>
                    <image>
                        <width>1280</width>
                        <height>800</height>
                    </image>
                    <clip>
                        <near>0.1</near>
                        <far>100</far>
                    </clip>
                </camera>
                <always_on>1</always_on>
                <update_rate>30</update_rate>
                <visualize>true</visualize>
                <pose>0 0.0375 0 0 0 0</pose>
            </sensor>
            <sensor name="observer_imu_sensor" type="imu">
                <always_on>1</always_on>
                <update_rate>200</update_rate>
                <visualize>false</visualize>
                <topic>observer/imu</topic>
            </sensor>
        </link>
        <joint name="base_joint" type="fixed">
            <parent>z_boom_link</parent>
            <child>base_link</child>
        </joint>

        <static>false</static>
        <self_collide>false</self_collide>

    </model>
</sdf>