<?xml version='1.0' encoding='ASCII'?>
<sdf version='1.7'>
  <world name='world_demo'>
    <gravity>0 0 -9.8</gravity>
    <physics type='ode'>
      <max_step_size>0.01</max_step_size>
      <real_time_factor>1</real_time_factor>
      <max_contacts>10</max_contacts>
    </physics>
    <plugin name='ignition::gazebo::systems::Physics' filename='libignition-gazebo-physics-system.so'/>
    <plugin name='ignition::gazebo::systems::UserCommands' filename='libignition-gazebo-user-commands-system.so'/>
    <plugin name='ignition::gazebo::systems::SceneBroadcaster' filename='libignition-gazebo-scene-broadcaster-system.so'/>
    <plugin name='ignition::gazebo::systems::Imu' filename='ignition-gazebo-imu-system'/>
    <plugin name='ignition::gazebo::systems::Sensors' filename='ignition-gazebo-sensors-system'>
    
      <render_engine>ogre2</render_engine>
    </plugin>

    <gui fullscreen="0">

      <!-- 3D scene -->
      <plugin filename="GzScene3D" name="3D View">
        <ignition-gui>
          <title>3D View</title>
          <property type="bool" key="showTitleBar">false</property>
          <property type="string" key="state">docked</property>
        </ignition-gui>

        <engine>ogre2</engine>
        <scene>scene</scene>
        <ambient_light>0.4 0.4 0.4</ambient_light>
        <background_color>0.8 0.8 0.8</background_color>
        <camera_pose>13.4 -6.1 2.23 0 0.4 -1.83</camera_pose>
      </plugin>

      <!-- World control -->
      <plugin filename="WorldControl" name="World control">
        <ignition-gui>
          <title>World control</title>
          <property type="bool" key="showTitleBar">false</property>
          <property type="bool" key="resizable">false</property>
          <property type="double" key="height">72</property>
          <property type="double" key="width">121</property>
          <property type="double" key="z">1</property>

          <property type="string" key="state">floating</property>
          <anchors target="3D View">
            <line own="left" target="left"/>
            <line own="bottom" target="bottom"/>
          </anchors>
        </ignition-gui>

        <play_pause>true</play_pause>
        <step>true</step>
        <start_paused>true</start_paused>

      </plugin>

      <!-- World statistics -->
      <plugin filename="WorldStats" name="World stats">
        <ignition-gui>
          <title>World stats</title>
          <property type="bool" key="showTitleBar">false</property>
          <property type="bool" key="resizable">false</property>
          <property type="double" key="height">110</property>
          <property type="double" key="width">290</property>
          <property type="double" key="z">1</property>

          <property type="string" key="state">floating</property>
          <anchors target="3D View">
            <line own="right" target="right"/>
            <line own="bottom" target="bottom"/>
          </anchors>
        </ignition-gui>

        <sim_time>true</sim_time>
        <real_time>true</real_time>
        <real_time_factor>true</real_time_factor>
        <iterations>true</iterations>
      </plugin>

      <plugin filename="TransformControl" name="Transform control">
          <ignition-gui>
              <property type="bool" key="showTitleBar">false</property>
              <property key="x" type="double">0</property>
              <property key="y" type="double">0</property>
              <property key="width" type="double">250</property>
              <property key="height" type="double">50</property>
              <property key="state" type="string">floating</property>
              <property key="cardBackground" type="string">#666666</property>
          </ignition-gui>
      </plugin>
      <plugin filename="Shapes" name="Shapes">
          <ignition-gui>
              <property type="bool" key="showTitleBar">false</property>
              <property key="x" type="double">250</property>
              <property key="y" type="double">0</property>
              <property key="width" type="double">150</property>
              <property key="height" type="double">50</property>
              <property key="state" type="string">floating</property>
              <property key="cardBackground" type="string">#666666</property>
          </ignition-gui>
      </plugin>
      <plugin filename="Screenshot" name="Screenshot">
          <ignition-gui>
              <property type="bool" key="showTitleBar">false</property>
              <property key="x" type="double">400</property>
              <property key="y" type="double">0</property>
              <property key="width" type="double">50</property>
              <property key="height" type="double">50</property>
              <property key="state" type="string">floating</property>
              <property key="cardBackground" type="string">#666666</property>
          </ignition-gui>
      </plugin>
      <plugin filename="ComponentInspector" name="Component inspector">
          <ignition-gui>
              <property key="x" type="double">0</property>
              <property key="y" type="double">0</property>
              <property key="width" type="double">400</property>
              <property key="height" type="double">375</property>
              <property key="state" type="string">docked_collapsed</property>
          </ignition-gui>
      </plugin>
      <plugin filename="EntityTree" name="Entity tree">
          <ignition-gui>
              <property key="x" type="double">0</property>
              <property key="y" type="double">0</property>
              <property key="width" type="double">400</property>
              <property key="height" type="double">375</property>
              <property key="state" type="string">docked_collapsed</property>
          </ignition-gui>
      </plugin>
    </gui>

    <scene>
      <ambient>1 1 1 1</ambient>
      <background>0.3 0.7 0.9 1</background>
      <shadows>0</shadows>
      <grid>false</grid>
    </scene>

    <light type="directional" name="sun">
      <cast_shadows>0</cast_shadows>
      <pose>-5 -3 10 0 0 0</pose>
      <diffuse>1 1 1 1</diffuse>
      <specular>1 1 1 1</specular>
      <direction>0 0 -1</direction>
    </light>

    <model name='ground_plane'>
      <static>true</static>
      <link name='link'>
        <collision name='collision'>
          <geometry>
            <plane>
              <normal>0.0 0.0 1</normal>
              <size>1 1</size>
            </plane>
          </geometry>
        </collision>
      </link>
      <pose>0 0 0 0 0 0</pose>
    </model>

    <!-- Base -->
    <include>
      <uri>
        https://fuel.ignitionrobotics.org/1.0/OpenRobotics/models/Warehouse
      </uri>
      <name>warehouse</name>
      <pose>0 0 -0.09 0 0 0</pose>
    </include>


    <!-- Carts -->

    <include>
      <uri>
        https://fuel.ignitionrobotics.org/1.0/MovAi/models/cart_model_2
      </uri>
      <name>cart1</name>
      <pose>-5.73 15 0.25 0 -0 0</pose>
    </include>

    <!-- Objects -->
    <include>
      <uri>
        https://fuel.ignitionrobotics.org/1.0/MovAi/models/shelf_big
      </uri>
      <name>shelf_big_0</name>
      <pose>-9.34177 -13.5598 0 0 -0 0</pose>
    </include>
    <include>
      <uri>
        https://fuel.ignitionrobotics.org/1.0/MovAi/models/shelf
      </uri>
      <name>shelf</name>
      <pose>-4.41528 -0.690987 0 0 -0 0</pose>
    </include>
    <include>
      <uri>
        https://fuel.ignitionrobotics.org/1.0/MovAi/models/shelf
      </uri>
      <name>shelf_0</name>
      <pose>-4.41528 2.30697 0 0 -0 0</pose>
    </include>
    <include>
      <uri>
        https://fuel.ignitionrobotics.org/1.0/MovAi/models/shelf
      </uri>
      <name>shelf_1</name>
      <pose>-4.41528 5.30708 0 0 -0 0</pose>
    </include>
    <include>
      <uri>
        https://fuel.ignitionrobotics.org/1.0/MovAi/models/shelf
      </uri>
      <name>shelf_2</name>
      <pose>-4.41528 8.34352 0 0 -0 0</pose>
    </include>
    <include>
      <uri>
        https://fuel.ignitionrobotics.org/1.0/MovAi/models/shelf
      </uri>
      <name>shelf_3</name>
      <pose>5.60144 8.34352 0 0 -0 0</pose>
    </include>
    <include>
      <uri>
        https://fuel.ignitionrobotics.org/1.0/MovAi/models/shelf
      </uri>
      <name>shelf_4</name>
      <pose>5.60144 5.30708 0 0 -0 0</pose>
    </include>
    <include>
      <uri>
        https://fuel.ignitionrobotics.org/1.0/MovAi/models/shelf
      </uri>
      <name>shelf_5</name>
      <pose>5.60144 -0.690987 0 0 -0 0</pose>
    </include>
    <include>
      <uri>
        https://fuel.ignitionrobotics.org/1.0/MovAi/models/shelf
      </uri>
      <name>shelf_6</name>
      <pose>5.60144 2.30697 0 0 -0 0</pose>
    </include>
    <include>
      <uri>
        https://fuel.ignitionrobotics.org/1.0/MovAi/models/pallet_box_mobile
      </uri>
      <name>pallet_box_mobile</name>
      <pose>4.4161 14.6952 0.01 0 -0 0</pose>
    </include>
    <include>
      <uri>
        https://fuel.ignitionrobotics.org/1.0/MovAi/models/pallet_box_mobile
      </uri>
      <name>pallet_box_mobile_0</name>
      <pose>4.45415 13.6212 0.01 0 -0 0</pose>
    </include>
    <include>
      <uri>
        https://fuel.ignitionrobotics.org/1.0/MovAi/models/pallet_box_mobile
      </uri>
      <name>pallet_box_mobile_1</name>
      <pose>4.4468 12.229 0.01 0 -0 0</pose>
    </include>
    <include>
      <uri>
        https://fuel.ignitionrobotics.org/1.0/MovAi/models/pallet_box_mobile
      </uri>
      <name>pallet_box</name>
      <pose>-6.11913 13.7079 0.01 0 -0 0</pose>
      <static>true</static>
    </include>
    <include>
      <uri>
        https://fuel.ignitionrobotics.org/1.0/MovAi/models/shelf_big
      </uri>
      <name>shelf_big_1</name>
      <pose>13.9821 15.319 0 0 -0 0</pose>
    </include>
    <include>
      <uri>
        https://fuel.ignitionrobotics.org/1.0/MovAi/models/shelf_big
      </uri>
      <name>shelf_big_2</name>
      <pose>6.19777 -12.9647 0 0 -0 0</pose>
    </include>
    <include>
      <uri>
        https://fuel.ignitionrobotics.org/1.0/MovAi/models/shelf_big
      </uri>
      <name>shelf_big_3</name>
      <pose>0.594376 -12.9647 0 0 -0 0</pose>
    </include>
    <include>
      <uri>
        https://fuel.ignitionrobotics.org/1.0/MovAi/models/shelf_big
      </uri>
      <name>shelf_big_4</name>
      <pose>-5.36284 -12.9647 0 0 -0 0</pose>
    </include>
    <include>
      <uri>
        https://fuel.ignitionrobotics.org/1.0/MovAi/models/shelf
      </uri>
      <name>shelf_7</name>
      <pose>13.3818 -21.2416 0 0 -0 0</pose>
    </include>
    <include>
      <uri>
        https://fuel.ignitionrobotics.org/1.0/MovAi/models/shelf
      </uri>
      <name>shelf_8</name>
      <pose>13.3818 -19.0028 0 0 -0 0</pose>
    </include>
    <include>
      <uri>
        https://fuel.ignitionrobotics.org/1.0/MovAi/models/shelf
      </uri>
      <name>shelf_9</name>
      <pose>13.3818 -16.4478 0 0 -0 0</pose>
    </include>
    <include>
      <uri>
        https://fuel.ignitionrobotics.org/1.0/MovAi/models/shelf
      </uri>
      <name>shelf_10</name>
      <pose>13.3818 -14.1028 0 0 -0 0</pose>
    </include>
    <include>
      <uri>
        https://fuel.ignitionrobotics.org/1.0/MovAi/models/pallet_box_mobile
      </uri>
      <name>pallet_box_0</name>
      <pose>14.0222 -24.335 0.01 0 -0 0</pose>
      <static>true</static>
    </include>

    <model name='observer'>
        <plugin name='dataset_generation::ObserverRobotController'
        filename='ObserverRobotController' />

        <pose>0 0 0 0 0 0</pose>

        <!-- Link for the base of the observer. The observer base is jointed to the world with two
        prismatic joints allowing XY motion -->
        <link name='observer_link'>
            <inertial>
                <mass>1</mass>
                <pose>0 0 0 0 0 0</pose>
            </inertial>
            <visual name='observer_base_visual'>
                <geometry>
                    <box>
                        <size>0.5 0.5 0.1</size>
                    </box>
                </geometry>
                <material>
                    <ambient>0 0 1 1</ambient>
                    <diffuse>0 0 1 1</diffuse>
                    <specular>1 1 1 1</specular>
                </material>
            </visual>
            <pose>0 0 0 0 0 0</pose>
        </link>
        <link name="x_slider_link" />
        <link name="z_rotator_link" />
        <joint name="world_x_slider" type="prismatic">
            <parent>world</parent>
            <child>x_slider_link</child>
            <axis>
                <xyz>1 0 0</xyz>
                <dynamics>
                    <damping>3.0</damping>
                    <friction>0.1</friction>
                </dynamics>
            </axis>
        </joint>
        <joint name="world_y_slider" type="prismatic">
            <parent>x_slider_link</parent>
            <child>z_rotator_link</child>
            <axis>
                <xyz>0 1 0</xyz>
                <dynamics>
                    <damping>3.0</damping>
                    <friction>0.1</friction>
                </dynamics>
            </axis>
        </joint>
        <joint name="z_rotator" type="revolute">
            <parent>z_rotator_link</parent>
            <child>observer_link</child>
            <axis>
                <xyz>0 0 1</xyz>
                <dynamics>
                    <damping>3.0</damping>
                    <friction>0.1</friction>
                </dynamics>
            </axis>
        </joint>

        <!-- The Z slider moves the base_link up and down -->
        <link name='z_slider_link'>
            <gravity>false</gravity>
            <visual name='z_slider_visual'>
                <geometry>
                    <box>
                        <size>0.1 0.1 2.5</size>
                    </box>
                </geometry>
                <material>
                    <ambient>1 0 0 1</ambient>
                    <diffuse>1 0 0 1</diffuse>
                    <specular>1 1 1 1</specular>
                </material>
            </visual>
            <pose>0 0 -0.25 0 0 0</pose>
        </link>
        <joint name="z_slider_joint" type="prismatic">
            <parent>observer_link</parent>
            <child>z_slider_link</child>
            <axis>
                <xyz>0 0 1</xyz>
                <limit>
                    <lower>-1</lower>
                    <upper>2.5</upper>
                </limit>
                <dynamics>
                    <damping>10.0</damping>
                    <friction>0.1</friction>
                </dynamics>
            </axis>
        </joint>

        <!-- The z_boom link extends forward from the top of the z_slider,
        this makes it more difficult to do pure rotations, which SLAM systems can struggle with. -->
        <link name='z_boom_link'>
            <gravity>false</gravity>
            <visual name='z_boom_visual'>
                <geometry>
                    <box>
                        <size>0.5 0.1 0.1</size>
                    </box>
                </geometry>
                <material>
                    <ambient>0 1 0 1</ambient>
                    <diffuse>0 1 0 1</diffuse>
                    <specular>1 1 1 1</specular>
                </material>
            </visual>
            <pose>0.25 0 1 0 0 0</pose>
        </link>
        <joint name="z_boom_joint" type="fixed">
            <parent>z_slider_link</parent>
            <child>z_boom_link</child>
        </joint>

        <!-- The base link is where all data is collected. It contains the IMU, 3 cameras (stereo
        and segmentation), and is where ground truth is recorded. -->
        <link name="base_link">
            <gravity>false</gravity>
            <visual name='base_visual'>
                <geometry>
                    <box>
                        <size>0.1 0.5 0.25</size>
                    </box>
                </geometry>
                <material>
                    <ambient>1 1 0 1</ambient>
                    <diffuse>1 1 0 1</diffuse>
                    <specular>1 1 1 1</specular>
                </material>
            </visual>
            <pose>0.5 0 1 0 0 0</pose>
            <sensor name='observer_camera' type='camera'>
                <topic>observer/left</topic>
                <camera>
                    <camera_info_topic>observer/left_info</camera_info_topic>

                    <horizontal_fov>1.047</horizontal_fov>
                    <image>
                        <width>1280</width>
                        <height>800</height>
                    </image>
                    <clip>
                        <near>0.1</near>
                        <far>100</far>
                    </clip>
                </camera>
                <always_on>1</always_on>
                <update_rate>30</update_rate>
                <visualize>true</visualize>
                <pose>0 -0.0375 0 0 0 0</pose>
            </sensor>
            <sensor name='observer_camera_right' type='camera'>
                <topic>observer/right</topic>
                <camera>
                    <horizontal_fov>0.6</horizontal_fov>
                    <image>
                        <width>1280</width>
                        <height>800</height>
                    </image>
                    <clip>
                        <near>0.1</near>
                        <far>100</far>
                    </clip>
                </camera>
                <always_on>1</always_on>
                <update_rate>30</update_rate>
                <visualize>true</visualize>
                <pose>0 0.0375 0 0 0 0</pose>
            </sensor>
            <sensor name="observer_imu_sensor" type="imu">
                <always_on>1</always_on>
                <update_rate>200</update_rate>
                <visualize>false</visualize>
                <topic>observer/imu</topic>
            </sensor>
        </link>
        <joint name="base_joint" type="fixed">
            <parent>z_boom_link</parent>
            <child>base_link</child>
        </joint>

        <static>false</static>
        <self_collide>false</self_collide>

    </model>
  </world>
</sdf>
